Workbook

Sheet 2025
A1: Meat & Cheese Best before based on production date from production tag | S1: Meat & Cheese Best before based on production date from production tag
A2: Produced | B2: Best before | C2: Best before | D2: Produced | E2: Best before | F2: Best before | G2: Produced | H2: Best before | I2: Best before | J2: Produced | K2: Best before | L2: Best before | M2: Produced | N2: Best before | O2: Best before | P2: Produced | Q2: Best before | R2: Best before | S2: Produced | T2: Best before | U2: Best before | V2: Produced | W2: Best before | X2: Best before | Y2: Produced | Z2: Best before | AA2: Best before | AB2: Produced | AC2: Best before | AD2: Best before | AE2: Produced | AF2: Best before | AG2: Best before | AH2: Produced | AI2: Best before | AJ2: Best before
A3: 45658 | B3: =+A3+130 -> 45788 | C3: =VLOOKUP('2025'!B3,Julian!$A$3:$G$367,7,FALSE) -> 25MA11 | D3: 45689 | E3: =+D3+130 -> 45819 | F3: =VLOOKUP('2025'!E3,Julian!$A$3:$G$367,7,FALSE) -> 25JN11 | G3: 45717 | H3: =+G3+130 -> 45847 | I3: =VLOOKUP('2025'!H3,Julian!$A$3:$G$367,7,FALSE) -> 25JL09 | J3: 45748 | K3: =+J3+130 -> 45878 | L3: =VLOOKUP('2025'!K3,Julian!$A$3:$G$367,7,FALSE) -> 25AU09 | M3: 45778 | N3: =+M3+130 -> 45908 | O3: =VLOOKUP('2025'!N3,Julian!$A$3:$G$367,7,FALSE) -> 25SE08 | P3: 45809 | Q3: =+P3+130 -> 45939 | R3: =VLOOKUP('2025'!Q3,Julian!$A$3:$G$367,7,FALSE) -> 25OC09 | S3: 45839 | T3: =+S3+130 -> 45969 | U3: =VLOOKUP('2025'!T3,Julian!$A$3:$G$367,7,FALSE) -> 25NO08 | V3: 45870 | W3: =+V3+130 -> 46000 | X3: =VLOOKUP('2025'!W3,Julian!$A$3:$G$367,7,FALSE) -> 25DE09 | Y3: 45901 | Z3: =+Y3+130 -> 46031 | AA3: =VLOOKUP('2025'!Z3,Julian!$A$3:$G$367,7,FALSE) -> 26JA09 | AB3: 45931 | AC3: =+AB3+130 -> 46061 | AD3: =VLOOKUP('2025'!AC3,Julian!$A$3:$G$367,7,FALSE) -> 26FE08 | AE3: 45962 | AF3: =+AE3+130 -> 46092 | AG3: =VLOOKUP('2025'!AF3,Julian!$A$3:$G$367,7,FALSE) -> 26MR11 | AH3: 45992 | AI3: =+AH3+130 -> 46122 | AJ3: =VLOOKUP('2025'!AI3,Julian!$A$3:$G$367,7,FALSE) -> 26AL10
A4: 45659 | B4: =+A4+130 -> 45789 | C4: =VLOOKUP('2025'!B4,Julian!$A$3:$G$367,7,FALSE) -> 25MA12 | D4: 45690 | E4: =+D4+130 -> 45820 | F4: =VLOOKUP('2025'!E4,Julian!$A$3:$G$367,7,FALSE) -> 25JN12 | G4: 45718 | H4: =+G4+130 -> 45848 | I4: =VLOOKUP('2025'!H4,Julian!$A$3:$G$367,7,FALSE) -> 25JL10 | J4: 45749 | K4: =+J4+130 -> 45879 | L4: =VLOOKUP('2025'!K4,Julian!$A$3:$G$367,7,FALSE) -> 25AU10 | M4: 45779 | N4: =+M4+130 -> 45909 | O4: =VLOOKUP('2025'!N4,Julian!$A$3:$G$367,7,FALSE) -> 25SE09 | P4: 45810 | Q4: =+P4+130 -> 45940 | R4: =VLOOKUP('2025'!Q4,Julian!$A$3:$G$367,7,FALSE) -> 25OC10 | S4: 45840 | T4: =+S4+130 -> 45970 | U4: =VLOOKUP('2025'!T4,Julian!$A$3:$G$367,7,FALSE) -> 25NO09 | V4: 45871 | W4: =+V4+130 -> 46001 | X4: =VLOOKUP('2025'!W4,Julian!$A$3:$G$367,7,FALSE) -> 25DE10 | Y4: 45902 | Z4: =+Y4+130 -> 46032 | AA4: =VLOOKUP('2025'!Z4,Julian!$A$3:$G$367,7,FALSE) -> 26JA10 | AB4: 45932 | AC4: =+AB4+130 -> 46062 | AD4: =VLOOKUP('2025'!AC4,Julian!$A$3:$G$367,7,FALSE) -> 26FE09 | AE4: 45963 | AF4: =+AE4+130 -> 46093 | AG4: =VLOOKUP('2025'!AF4,Julian!$A$3:$G$367,7,FALSE) -> 26MR12 | AH4: 45993 | AI4: =+AH4+130 -> 46123 | AJ4: =VLOOKUP('2025'!AI4,Julian!$A$3:$G$367,7,FALSE) -> 26AL11
A5: 45660 | B5: =+A5+130 -> 45790 | C5: =VLOOKUP('2025'!B5,Julian!$A$3:$G$367,7,FALSE) -> 25MA13 | D5: 45691 | E5: =+D5+130 -> 45821 | F5: =VLOOKUP('2025'!E5,Julian!$A$3:$G$367,7,FALSE) -> 25JN13 | G5: 45719 | H5: =+G5+130 -> 45849 | I5: =VLOOKUP('2025'!H5,Julian!$A$3:$G$367,7,FALSE) -> 25JL11 | J5: 45750 | K5: =+J5+130 -> 45880 | L5: =VLOOKUP('2025'!K5,Julian!$A$3:$G$367,7,FALSE) -> 25AU11 | M5: 45780 | N5: =+M5+130 -> 45910 | O5: =VLOOKUP('2025'!N5,Julian!$A$3:$G$367,7,FALSE) -> 25SE10 | P5: 45811 | Q5: =+P5+130 -> 45941 | R5: =VLOOKUP('2025'!Q5,Julian!$A$3:$G$367,7,FALSE) -> 25OC11 | S5: 45841 | T5: =+S5+130 -> 45971 | U5: =VLOOKUP('2025'!T5,Julian!$A$3:$G$367,7,FALSE) -> 25NO10 | V5: 45872 | W5: =+V5+130 -> 46002 | X5: =VLOOKUP('2025'!W5,Julian!$A$3:$G$367,7,FALSE) -> 25DE11 | Y5: 45903 | Z5: =+Y5+130 -> 46033 | AA5: =VLOOKUP('2025'!Z5,Julian!$A$3:$G$367,7,FALSE) -> 26JA11 | AB5: 45933 | AC5: =+AB5+130 -> 46063 | AD5: =VLOOKUP('2025'!AC5,Julian!$A$3:$G$367,7,FALSE) -> 26FE10 | AE5: 45964 | AF5: =+AE5+130 -> 46094 | AG5: =VLOOKUP('2025'!AF5,Julian!$A$3:$G$367,7,FALSE) -> 26MR13 | AH5: 45994 | AI5: =+AH5+130 -> 46124 | AJ5: =VLOOKUP('2025'!AI5,Julian!$A$3:$G$367,7,FALSE) -> 26AL12
A6: 45661 | B6: =+A6+130 -> 45791 | C6: =VLOOKUP('2025'!B6,Julian!$A$3:$G$367,7,FALSE) -> 25MA14 | D6: 45692 | E6: =+D6+130 -> 45822 | F6: =VLOOKUP('2025'!E6,Julian!$A$3:$G$367,7,FALSE) -> 25JN14 | G6: 45720 | H6: =+G6+130 -> 45850 | I6: =VLOOKUP('2025'!H6,Julian!$A$3:$G$367,7,FALSE) -> 25JL12 | J6: 45751 | K6: =+J6+130 -> 45881 | L6: =VLOOKUP('2025'!K6,Julian!$A$3:$G$367,7,FALSE) -> 25AU12 | M6: 45781 | N6: =+M6+130 -> 45911 | O6: =VLOOKUP('2025'!N6,Julian!$A$3:$G$367,7,FALSE) -> 25SE11 | P6: 45812 | Q6: =+P6+130 -> 45942 | R6: =VLOOKUP('2025'!Q6,Julian!$A$3:$G$367,7,FALSE) -> 25OC12 | S6: 45842 | T6: =+S6+130 -> 45972 | U6: =VLOOKUP('2025'!T6,Julian!$A$3:$G$367,7,FALSE) -> 25NO11 | V6: 45873 | W6: =+V6+130 -> 46003 | X6: =VLOOKUP('2025'!W6,Julian!$A$3:$G$367,7,FALSE) -> 25DE12 | Y6: 45904 | Z6: =+Y6+130 -> 46034 | AA6: =VLOOKUP('2025'!Z6,Julian!$A$3:$G$367,7,FALSE) -> 26JA12 | AB6: 45934 | AC6: =+AB6+130 -> 46064 | AD6: =VLOOKUP('2025'!AC6,Julian!$A$3:$G$367,7,FALSE) -> 26FE11 | AE6: 45965 | AF6: =+AE6+130 -> 46095 | AG6: =VLOOKUP('2025'!AF6,Julian!$A$3:$G$367,7,FALSE) -> 26MR14 | AH6: 45995 | AI6: =+AH6+130 -> 46125 | AJ6: =VLOOKUP('2025'!AI6,Julian!$A$3:$G$367,7,FALSE) -> 26AL13
A7: 45662 | B7: =+A7+130 -> 45792 | C7: =VLOOKUP('2025'!B7,Julian!$A$3:$G$367,7,FALSE) -> 25MA15 | D7: 45693 | E7: =+D7+130 -> 45823 | F7: =VLOOKUP('2025'!E7,Julian!$A$3:$G$367,7,FALSE) -> 25JN15 | G7: 45721 | H7: =+G7+130 -> 45851 | I7: =VLOOKUP('2025'!H7,Julian!$A$3:$G$367,7,FALSE) -> 25JL13 | J7: 45752 | K7: =+J7+130 -> 45882 | L7: =VLOOKUP('2025'!K7,Julian!$A$3:$G$367,7,FALSE) -> 25AU13 | M7: 45782 | N7: =+M7+130 -> 45912 | O7: =VLOOKUP('2025'!N7,Julian!$A$3:$G$367,7,FALSE) -> 25SE12 | P7: 45813 | Q7: =+P7+130 -> 45943 | R7: =VLOOKUP('2025'!Q7,Julian!$A$3:$G$367,7,FALSE) -> 25OC13 | S7: 45843 | T7: =+S7+130 -> 45973 | U7: =VLOOKUP('2025'!T7,Julian!$A$3:$G$367,7,FALSE) -> 25NO12 | V7: 45874 | W7: =+V7+130 -> 46004 | X7: =VLOOKUP('2025'!W7,Julian!$A$3:$G$367,7,FALSE) -> 25DE13 | Y7: 45905 | Z7: =+Y7+130 -> 46035 | AA7: =VLOOKUP('2025'!Z7,Julian!$A$3:$G$367,7,FALSE) -> 26JA13 | AB7: 45935 | AC7: =+AB7+130 -> 46065 | AD7: =VLOOKUP('2025'!AC7,Julian!$A$3:$G$367,7,FALSE) -> 26FE12 | AE7: 45966 | AF7: =+AE7+130 -> 46096 | AG7: =VLOOKUP('2025'!AF7,Julian!$A$3:$G$367,7,FALSE) -> 26MR15 | AH7: 45996 | AI7: =+AH7+130 -> 46126 | AJ7: =VLOOKUP('2025'!AI7,Julian!$A$3:$G$367,7,FALSE) -> 26AL14
A8: 45663 | B8: =+A8+130 -> 45793 | C8: =VLOOKUP('2025'!B8,Julian!$A$3:$G$367,7,FALSE) -> 25MA16 | D8: 45694 | E8: =+D8+130 -> 45824 | F8: =VLOOKUP('2025'!E8,Julian!$A$3:$G$367,7,FALSE) -> 25JN16 | G8: 45722 | H8: =+G8+130 -> 45852 | I8: =VLOOKUP('2025'!H8,Julian!$A$3:$G$367,7,FALSE) -> 25JL14 | J8: 45753 | K8: =+J8+130 -> 45883 | L8: =VLOOKUP('2025'!K8,Julian!$A$3:$G$367,7,FALSE) -> 25AU14 | M8: 45783 | N8: =+M8+130 -> 45913 | O8: =VLOOKUP('2025'!N8,Julian!$A$3:$G$367,7,FALSE) -> 25SE13 | P8: 45814 | Q8: =+P8+130 -> 45944 | R8: =VLOOKUP('2025'!Q8,Julian!$A$3:$G$367,7,FALSE) -> 25OC14 | S8: 45844 | T8: =+S8+130 -> 45974 | U8: =VLOOKUP('2025'!T8,Julian!$A$3:$G$367,7,FALSE) -> 25NO13 | V8: 45875 | W8: =+V8+130 -> 46005 | X8: =VLOOKUP('2025'!W8,Julian!$A$3:$G$367,7,FALSE) -> 25DE14 | Y8: 45906 | Z8: =+Y8+130 -> 46036 | AA8: =VLOOKUP('2025'!Z8,Julian!$A$3:$G$367,7,FALSE) -> 26JA14 | AB8: 45936 | AC8: =+AB8+130 -> 46066 | AD8: =VLOOKUP('2025'!AC8,Julian!$A$3:$G$367,7,FALSE) -> 26FE13 | AE8: 45967 | AF8: =+AE8+130 -> 46097 | AG8: =VLOOKUP('2025'!AF8,Julian!$A$3:$G$367,7,FALSE) -> 26MR16 | AH8: 45997 | AI8: =+AH8+130 -> 46127 | AJ8: =VLOOKUP('2025'!AI8,Julian!$A$3:$G$367,7,FALSE) -> 26AL15
A9: 45664 | B9: =+A9+130 -> 45794 | C9: =VLOOKUP('2025'!B9,Julian!$A$3:$G$367,7,FALSE) -> 25MA17 | D9: 45695 | E9: =+D9+130 -> 45825 | F9: =VLOOKUP('2025'!E9,Julian!$A$3:$G$367,7,FALSE) -> 25JN17 | G9: 45723 | H9: =+G9+130 -> 45853 | I9: =VLOOKUP('2025'!H9,Julian!$A$3:$G$367,7,FALSE) -> 25JL15 | J9: 45754 | K9: =+J9+130 -> 45884 | L9: =VLOOKUP('2025'!K9,Julian!$A$3:$G$367,7,FALSE) -> 25AU15 | M9: 45784 | N9: =+M9+130 -> 45914 | O9: =VLOOKUP('2025'!N9,Julian!$A$3:$G$367,7,FALSE) -> 25SE14 | P9: 45815 | Q9: =+P9+130 -> 45945 | R9: =VLOOKUP('2025'!Q9,Julian!$A$3:$G$367,7,FALSE) -> 25OC15 | S9: 45845 | T9: =+S9+130 -> 45975 | U9: =VLOOKUP('2025'!T9,Julian!$A$3:$G$367,7,FALSE) -> 25NO14 | V9: 45876 | W9: =+V9+130 -> 46006 | X9: =VLOOKUP('2025'!W9,Julian!$A$3:$G$367,7,FALSE) -> 25DE15 | Y9: 45907 | Z9: =+Y9+130 -> 46037 | AA9: =VLOOKUP('2025'!Z9,Julian!$A$3:$G$367,7,FALSE) -> 26JA15 | AB9: 45937 | AC9: =+AB9+130 -> 46067 | AD9: =VLOOKUP('2025'!AC9,Julian!$A$3:$G$367,7,FALSE) -> 26FE14 | AE9: 45968 | AF9: =+AE9+130 -> 46098 | AG9: =VLOOKUP('2025'!AF9,Julian!$A$3:$G$367,7,FALSE) -> 26MR17 | AH9: 45998 | AI9: =+AH9+130 -> 46128 | AJ9: =VLOOKUP('2025'!AI9,Julian!$A$3:$G$367,7,FALSE) -> 26AL16
A10: 45665 | B10: =+A10+130 -> 45795 | C10: =VLOOKUP('2025'!B10,Julian!$A$3:$G$367,7,FALSE) -> 25MA18 | D10: 45696 | E10: =+D10+130 -> 45826 | F10: =VLOOKUP('2025'!E10,Julian!$A$3:$G$367,7,FALSE) -> 25JN18 | G10: 45724 | H10: =+G10+130 -> 45854 | I10: =VLOOKUP('2025'!H10,Julian!$A$3:$G$367,7,FALSE) -> 25JL16 | J10: 45755 | K10: =+J10+130 -> 45885 | L10: =VLOOKUP('2025'!K10,Julian!$A$3:$G$367,7,FALSE) -> 25AU16 | M10: 45785 | N10: =+M10+130 -> 45915 | O10: =VLOOKUP('2025'!N10,Julian!$A$3:$G$367,7,FALSE) -> 25SE15 | P10: 45816 | Q10: =+P10+130 -> 45946 | R10: =VLOOKUP('2025'!Q10,Julian!$A$3:$G$367,7,FALSE) -> 25OC16 | S10: 45846 | T10: =+S10+130 -> 45976 | U10: =VLOOKUP('2025'!T10,Julian!$A$3:$G$367,7,FALSE) -> 25NO15 | V10: 45877 | W10: =+V10+130 -> 46007 | X10: =VLOOKUP('2025'!W10,Julian!$A$3:$G$367,7,FALSE) -> 25DE16 | Y10: 45908 | Z10: =+Y10+130 -> 46038 | AA10: =VLOOKUP('2025'!Z10,Julian!$A$3:$G$367,7,FALSE) -> 26JA16 | AB10: 45938 | AC10: =+AB10+130 -> 46068 | AD10: =VLOOKUP('2025'!AC10,Julian!$A$3:$G$367,7,FALSE) -> 26FE15 | AE10: 45969 | AF10: =+AE10+130 -> 46099 | AG10: =VLOOKUP('2025'!AF10,Julian!$A$3:$G$367,7,FALSE) -> 26MR18 | AH10: 45999 | AI10: =+AH10+130 -> 46129 | AJ10: =VLOOKUP('2025'!AI10,Julian!$A$3:$G$367,7,FALSE) -> 26AL17
A11: 45666 | B11: =+A11+130 -> 45796 | C11: =VLOOKUP('2025'!B11,Julian!$A$3:$G$367,7,FALSE) -> 25MA19 | D11: 45697 | E11: =+D11+130 -> 45827 | F11: =VLOOKUP('2025'!E11,Julian!$A$3:$G$367,7,FALSE) -> 25JN19 | G11: 45725 | H11: =+G11+130 -> 45855 | I11: =VLOOKUP('2025'!H11,Julian!$A$3:$G$367,7,FALSE) -> 25JL17 | J11: 45756 | K11: =+J11+130 -> 45886 | L11: =VLOOKUP('2025'!K11,Julian!$A$3:$G$367,7,FALSE) -> 25AU17 | M11: 45786 | N11: =+M11+130 -> 45916 | O11: =VLOOKUP('2025'!N11,Julian!$A$3:$G$367,7,FALSE) -> 25SE16 | P11: 45817 | Q11: =+P11+130 -> 45947 | R11: =VLOOKUP('2025'!Q11,Julian!$A$3:$G$367,7,FALSE) -> 25OC17 | S11: 45847 | T11: =+S11+130 -> 45977 | U11: =VLOOKUP('2025'!T11,Julian!$A$3:$G$367,7,FALSE) -> 25NO16 | V11: 45878 | W11: =+V11+130 -> 46008 | X11: =VLOOKUP('2025'!W11,Julian!$A$3:$G$367,7,FALSE) -> 25DE17 | Y11: 45909 | Z11: =+Y11+130 -> 46039 | AA11: =VLOOKUP('2025'!Z11,Julian!$A$3:$G$367,7,FALSE) -> 26JA17 | AB11: 45939 | AC11: =+AB11+130 -> 46069 | AD11: =VLOOKUP('2025'!AC11,Julian!$A$3:$G$367,7,FALSE) -> 26FE16 | AE11: 45970 | AF11: =+AE11+130 -> 46100 | AG11: =VLOOKUP('2025'!AF11,Julian!$A$3:$G$367,7,FALSE) -> 26MR19 | AH11: 46000 | AI11: =+AH11+130 -> 46130 | AJ11: =VLOOKUP('2025'!AI11,Julian!$A$3:$G$367,7,FALSE) -> 26AL18
A12: 45667 | B12: =+A12+130 -> 45797 | C12: =VLOOKUP('2025'!B12,Julian!$A$3:$G$367,7,FALSE) -> 25MA20 | D12: 45698 | E12: =+D12+130 -> 45828 | F12: =VLOOKUP('2025'!E12,Julian!$A$3:$G$367,7,FALSE) -> 25JN20 | G12: 45726 | H12: =+G12+130 -> 45856 | I12: =VLOOKUP('2025'!H12,Julian!$A$3:$G$367,7,FALSE) -> 25JL18 | J12: 45757 | K12: =+J12+130 -> 45887 | L12: =VLOOKUP('2025'!K12,Julian!$A$3:$G$367,7,FALSE) -> 25AU18 | M12: 45787 | N12: =+M12+130 -> 45917 | O12: =VLOOKUP('2025'!N12,Julian!$A$3:$G$367,7,FALSE) -> 25SE17 | P12: 45818 | Q12: =+P12+130 -> 45948 | R12: =VLOOKUP('2025'!Q12,Julian!$A$3:$G$367,7,FALSE) -> 25OC18 | S12: 45848 | T12: =+S12+130 -> 45978 | U12: =VLOOKUP('2025'!T12,Julian!$A$3:$G$367,7,FALSE) -> 25NO17 | V12: 45879 | W12: =+V12+130 -> 46009 | X12: =VLOOKUP('2025'!W12,Julian!$A$3:$G$367,7,FALSE) -> 25DE18 | Y12: 45910 | Z12: =+Y12+130 -> 46040 | AA12: =VLOOKUP('2025'!Z12,Julian!$A$3:$G$367,7,FALSE) -> 26JA18 | AB12: 45940 | AC12: =+AB12+130 -> 46070 | AD12: =VLOOKUP('2025'!AC12,Julian!$A$3:$G$367,7,FALSE) -> 26FE17 | AE12: 45971 | AF12: =+AE12+130 -> 46101 | AG12: =VLOOKUP('2025'!AF12,Julian!$A$3:$G$367,7,FALSE) -> 26MR20 | AH12: 46001 | AI12: =+AH12+130 -> 46131 | AJ12: =VLOOKUP('2025'!AI12,Julian!$A$3:$G$367,7,FALSE) -> 26AL19
A13: 45668 | B13: =+A13+130 -> 45798 | C13: =VLOOKUP('2025'!B13,Julian!$A$3:$G$367,7,FALSE) -> 25MA21 | D13: 45699 | E13: =+D13+130 -> 45829 | F13: =VLOOKUP('2025'!E13,Julian!$A$3:$G$367,7,FALSE) -> 25JN21 | G13: 45727 | H13: =+G13+130 -> 45857 | I13: =VLOOKUP('2025'!H13,Julian!$A$3:$G$367,7,FALSE) -> 25JL19 | J13: 45758 | K13: =+J13+130 -> 45888 | L13: =VLOOKUP('2025'!K13,Julian!$A$3:$G$367,7,FALSE) -> 25AU19 | M13: 45788 | N13: =+M13+130 -> 45918 | O13: =VLOOKUP('2025'!N13,Julian!$A$3:$G$367,7,FALSE) -> 25SE18 | P13: 45819 | Q13: =+P13+130 -> 45949 | R13: =VLOOKUP('2025'!Q13,Julian!$A$3:$G$367,7,FALSE) -> 25OC19 | S13: 45849 | T13: =+S13+130 -> 45979 | U13: =VLOOKUP('2025'!T13,Julian!$A$3:$G$367,7,FALSE) -> 25NO18 | V13: 45880 | W13: =+V13+130 -> 46010 | X13: =VLOOKUP('2025'!W13,Julian!$A$3:$G$367,7,FALSE) -> 25DE19 | Y13: 45911 | Z13: =+Y13+130 -> 46041 | AA13: =VLOOKUP('2025'!Z13,Julian!$A$3:$G$367,7,FALSE) -> 26JA19 | AB13: 45941 | AC13: =+AB13+130 -> 46071 | AD13: =VLOOKUP('2025'!AC13,Julian!$A$3:$G$367,7,FALSE) -> 26FE18 | AE13: 45972 | AF13: =+AE13+130 -> 46102 | AG13: =VLOOKUP('2025'!AF13,Julian!$A$3:$G$367,7,FALSE) -> 26MR21 | AH13: 46002 | AI13: =+AH13+130 -> 46132 | AJ13: =VLOOKUP('2025'!AI13,Julian!$A$3:$G$367,7,FALSE) -> 26AL20
A14: 45669 | B14: =+A14+130 -> 45799 | C14: =VLOOKUP('2025'!B14,Julian!$A$3:$G$367,7,FALSE) -> 25MA22 | D14: 45700 | E14: =+D14+130 -> 45830 | F14: =VLOOKUP('2025'!E14,Julian!$A$3:$G$367,7,FALSE) -> 25JN22 | G14: 45728 | H14: =+G14+130 -> 45858 | I14: =VLOOKUP('2025'!H14,Julian!$A$3:$G$367,7,FALSE) -> 25JL20 | J14: 45759 | K14: =+J14+130 -> 45889 | L14: =VLOOKUP('2025'!K14,Julian!$A$3:$G$367,7,FALSE) -> 25AU20 | M14: 45789 | N14: =+M14+130 -> 45919 | O14: =VLOOKUP('2025'!N14,Julian!$A$3:$G$367,7,FALSE) -> 25SE19 | P14: 45820 | Q14: =+P14+130 -> 45950 | R14: =VLOOKUP('2025'!Q14,Julian!$A$3:$G$367,7,FALSE) -> 25OC20 | S14: 45850 | T14: =+S14+130 -> 45980 | U14: =VLOOKUP('2025'!T14,Julian!$A$3:$G$367,7,FALSE) -> 25NO19 | V14: 45881 | W14: =+V14+130 -> 46011 | X14: =VLOOKUP('2025'!W14,Julian!$A$3:$G$367,7,FALSE) -> 25DE20 | Y14: 45912 | Z14: =+Y14+130 -> 46042 | AA14: =VLOOKUP('2025'!Z14,Julian!$A$3:$G$367,7,FALSE) -> 26JA20 | AB14: 45942 | AC14: =+AB14+130 -> 46072 | AD14: =VLOOKUP('2025'!AC14,Julian!$A$3:$G$367,7,FALSE) -> 26FE19 | AE14: 45973 | AF14: =+AE14+130 -> 46103 | AG14: =VLOOKUP('2025'!AF14,Julian!$A$3:$G$367,7,FALSE) -> 26MR22 | AH14: 46003 | AI14: =+AH14+130 -> 46133 | AJ14: =VLOOKUP('2025'!AI14,Julian!$A$3:$G$367,7,FALSE) -> 26AL21
... A30: 45685 | B30: =+A30+130 -> 45815 | C30: =VLOOKUP('2025'!B30,Julian!$A$3:$G$367,7,FALSE) -> 25JN07 | D30: 45716 | E30: =+D30+130 -> 45846 | F30: =VLOOKUP('2025'!E30,Julian!$A$3:$G$367,7,FALSE) -> 25JL08 | G30: 45744 | H30: =+G30+130 -> 45874 | I30: =VLOOKUP('2025'!H30,Julian!$A$3:$G$367,7,FALSE) -> 25AU05 | J30: 45775 | K30: =+J30+130 -> 45905 | L30: =VLOOKUP('2025'!K30,Julian!$A$3:$G$367,7,FALSE) -> 25SE05 | M30: 45805 | N30: =+M30+130 -> 45935 | O30: =VLOOKUP('2025'!N30,Julian!$A$3:$G$367,7,FALSE) -> 25OC05 | P30: 45836 | Q30: =+P30+130 -> 45966 | R30: =VLOOKUP('2025'!Q30,Julian!$A$3:$G$367,7,FALSE) -> 25NO05 | S30: 45866 | T30: =+S30+130 -> 45996 | U30: =VLOOKUP('2025'!T30,Julian!$A$3:$G$367,7,FALSE) -> 25DE05 | V30: 45897 | W30: =+V30+130 -> 46027 | X30: =VLOOKUP('2025'!W30,Julian!$A$3:$G$367,7,FALSE) -> 26JA05 | Y30: 45928 | Z30: =+Y30+130 -> 46058 | AA30: =VLOOKUP('2025'!Z30,Julian!$A$3:$G$367,7,FALSE) -> 26FE05 | AB30: 45958 | AC30: =+AB30+130 -> 46088 | AD30: =VLOOKUP('2025'!AC30,Julian!$A$3:$G$367,7,FALSE) -> 26MR07 | AE30: 45989 | AF30: =+AE30+130 -> 46119 | AG30: =VLOOKUP('2025'!AF30,Julian!$A$3:$G$367,7,FALSE) -> 26AL07 | AH30: 46019 | AI30: =+AH30+130 -> 46149 | AJ30: =VLOOKUP('2025'!AI30,Julian!$A$3:$G$367,7,FALSE) -> 26MA07
A31: 45686 | B31: =+A31+130 -> 45816 | C31: =VLOOKUP('2025'!B31,Julian!$A$3:$G$367,7,FALSE) -> 25JN08 | G31: 45745 | H31: =+G31+130 -> 45875 | I31: =VLOOKUP('2025'!H31,Julian!$A$3:$G$367,7,FALSE) -> 25AU06 | J31: 45776 | K31: =+J31+130 -> 45906 | L31: =VLOOKUP('2025'!K31,Julian!$A$3:$G$367,7,FALSE) -> 25SE06 | M31: 45806 | N31: =+M31+130 -> 45936 | O31: =VLOOKUP('2025'!N31,Julian!$A$3:$G$367,7,FALSE) -> 25OC06 | P31: 45837 | Q31: =+P31+130 -> 45967 | R31: =VLOOKUP('2025'!Q31,Julian!$A$3:$G$367,7,FALSE) -> 25NO06 | S31: 45867 | T31: =+S31+130 -> 45997 | U31: =VLOOKUP('2025'!T31,Julian!$A$3:$G$367,7,FALSE) -> 25DE06 | V31: 45898 | W31: =+V31+130 -> 46028 | X31: =VLOOKUP('2025'!W31,Julian!$A$3:$G$367,7,FALSE) -> 26JA06 | Y31: 45929 | Z31: =+Y31+130 -> 46059 | AA31: =VLOOKUP('2025'!Z31,Julian!$A$3:$G$367,7,FALSE) -> 26FE06 | AB31: 45959 | AC31: =+AB31+130 -> 46089 | AD31: =VLOOKUP('2025'!AC31,Julian!$A$3:$G$367,7,FALSE) -> 26MR08 | AE31: 45990 | AF31: =+AE31+130 -> 46120 | AG31: =VLOOKUP('2025'!AF31,Julian!$A$3:$G$367,7,FALSE) -> 26AL08 | AH31: 46020 | AI31: =+AH31+130 -> 46150 | AJ31: =VLOOKUP('2025'!AI31,Julian!$A$3:$G$367,7,FALSE) -> 26MA08
A32: 45687 | B32: =+A32+130 -> 45817 | C32: =VLOOKUP('2025'!B32,Julian!$A$3:$G$367,7,FALSE) -> 25JN09 | G32: 45746 | H32: =+G32+130 -> 45876 | I32: =VLOOKUP('2025'!H32,Julian!$A$3:$G$367,7,FALSE) -> 25AU07 | J32: 45777 | K32: =+J32+130 -> 45907 | L32: =VLOOKUP('2025'!K32,Julian!$A$3:$G$367,7,FALSE) -> 25SE07 | M32: 45807 | N32: =+M32+130 -> 45937 | O32: =VLOOKUP('2025'!N32,Julian!$A$3:$G$367,7,FALSE) -> 25OC07 | P32: 45838 | Q32: =+P32+130 -> 45968 | R32: =VLOOKUP('2025'!Q32,Julian!$A$3:$G$367,7,FALSE) -> 25NO07 | S32: 45868 | T32: =+S32+130 -> 45998 | U32: =VLOOKUP('2025'!T32,Julian!$A$3:$G$367,7,FALSE) -> 25DE07 | V32: 45899 | W32: =+V32+130 -> 46029 | X32: =VLOOKUP('2025'!W32,Julian!$A$3:$G$367,7,FALSE) -> 26JA07 | Y32: 45930 | Z32: =+Y32+130 -> 46060 | AA32: =VLOOKUP('2025'!Z32,Julian!$A$3:$G$367,7,FALSE) -> 26FE07 | AB32: 45960 | AC32: =+AB32+130 -> 46090 | AD32: =VLOOKUP('2025'!AC32,Julian!$A$3:$G$367,7,FALSE) -> 26MR09 | AE32: 45991 | AF32: =+AE32+130 -> 46121 | AG32: =VLOOKUP('2025'!AF32,Julian!$A$3:$G$367,7,FALSE) -> 26AL09 | AH32: 46021 | AI32: =+AH32+130 -> 46151 | AJ32: =VLOOKUP('2025'!AI32,Julian!$A$3:$G$367,7,FALSE) -> 26MA09
A33: 45688 | B33: =+A33+130 -> 45818 | C33: =VLOOKUP('2025'!B33,Julian!$A$3:$G$367,7,FALSE) -> 25JN10 | G33: 45747 | H33: =+G33+130 -> 45877 | I33: =VLOOKUP('2025'!H33,Julian!$A$3:$G$367,7,FALSE) -> 25AU08 | M33: 45808 | N33: =+M33+130 -> 45938 | O33: =VLOOKUP('2025'!N33,Julian!$A$3:$G$367,7,FALSE) -> 25OC08 | S33: 45869 | T33: =+S33+130 -> 45999 | U33: =VLOOKUP('2025'!T33,Julian!$A$3:$G$367,7,FALSE) -> 25DE08 | V33: 45900 | W33: =+V33+130 -> 46030 | X33: =VLOOKUP('2025'!W33,Julian!$A$3:$G$367,7,FALSE) -> 26JA08 | AB33: 45961 | AC33: =+AB33+130 -> 46091 | AD33: =VLOOKUP('2025'!AC33,Julian!$A$3:$G$367,7,FALSE) -> 26MR10 | AH33: 46022 | AI33: =+AH33+130 -> 46152 | AJ33: =VLOOKUP('2025'!AI33,Julian!$A$3:$G$367,7,FALSE) -> 26MA10
A34: Check cheese Best before and if it is shorter than the meat, use Cheese's best before | S34: Check cheese Best before and if it is shorter than the meat, use Cheese's best before

Sheet Julian
A3: =+'2025'!B3 -> 45788 | B3: =DAY(A3) -> 11 | C3: =TEXT(B3,"00") -> 11 | D3: =+TEXT(A3,"mmm") -> May | E3: =+TEXT(A3,"yy") -> 25 | F3: =VLOOKUP(D3,$I$3:$J$14,2,FALSE) -> MA | G3: =+E3&F3&C3 -> 25MA11 | I3: Jan | J3: JA
A4: =+'2025'!B4 -> 45789 | B4: =DAY(A4) -> 12 | C4: =TEXT(B4,"00") -> 12 | D4: =+TEXT(A4,"mmm") -> May | E4: =+TEXT(A4,"yy") -> 25 | F4: =VLOOKUP(D4,$I$3:$J$14,2,FALSE) -> MA | G4: =+E4&F4&C4 -> 25MA12 | I4: Feb | J4: FE
A5: =+'2025'!B5 -> 45790 | B5: =DAY(A5) -> 13 | C5: =TEXT(B5,"00") -> 13 | D5: =+TEXT(A5,"mmm") -> May | E5: =+TEXT(A5,"yy") -> 25 | F5: =VLOOKUP(D5,$I$3:$J$14,2,FALSE) -> MA | G5: =+E5&F5&C5 -> 25MA13 | I5: Mar | J5: MR
A6: =+'2025'!B6 -> 45791 | B6: =DAY(A6) -> 14 | C6: =TEXT(B6,"00") -> 14 | D6: =+TEXT(A6,"mmm") -> May | E6: =+TEXT(A6,"yy") -> 25 | F6: =VLOOKUP(D6,$I$3:$J$14,2,FALSE) -> MA | G6: =+E6&F6&C6 -> 25MA14 | I6: Apr | J6: AL
A7: =+'2025'!B7 -> 45792 | B7: =DAY(A7) -> 15 | C7: =TEXT(B7,"00") -> 15 | D7: =+TEXT(A7,"mmm") -> May | E7: =+TEXT(A7,"yy") -> 25 | F7: =VLOOKUP(D7,$I$3:$J$14,2,FALSE) -> MA | G7: =+E7&F7&C7 -> 25MA15 | I7: May | J7: MA
A8: =+'2025'!B8 -> 45793 | B8: =DAY(A8) -> 16 | C8: =TEXT(B8,"00") -> 16 | D8: =+TEXT(A8,"mmm") -> May | E8: =+TEXT(A8,"yy") -> 25 | F8: =VLOOKUP(D8,$I$3:$J$14,2,FALSE) -> MA | G8: =+E8&F8&C8 -> 25MA16 | I8: Jun | J8: JN
A9: =+'2025'!B9 -> 45794 | B9: =DAY(A9) -> 17 | C9: =TEXT(B9,"00") -> 17 | D9: =+TEXT(A9,"mmm") -> May | E9: =+TEXT(A9,"yy") -> 25 | F9: =VLOOKUP(D9,$I$3:$J$14,2,FALSE) -> MA | G9: =+E9&F9&C9 -> 25MA17 | I9: Jul | J9: JL
A10: =+'2025'!B10 -> 45795 | B10: =DAY(A10) -> 18 | C10: =TEXT(B10,"00") -> 18 | D10: =+TEXT(A10,"mmm") -> May | E10: =+TEXT(A10,"yy") -> 25 | F10: =VLOOKUP(D10,$I$3:$J$14,2,FALSE) -> MA | G10: =+E10&F10&C10 -> 25MA18 | I10: Aug | J10: AU
A11: =+'2025'!B11 -> 45796 | B11: =DAY(A11) -> 19 | C11: =TEXT(B11,"00") -> 19 | D11: =+TEXT(A11,"mmm") -> May | E11: =+TEXT(A11,"yy") -> 25 | F11: =VLOOKUP(D11,$I$3:$J$14,2,FALSE) -> MA | G11: =+E11&F11&C11 -> 25MA19 | I11: Sep | J11: SE
A12: =+'2025'!B12 -> 45797 | B12: =DAY(A12) -> 20 | C12: =TEXT(B12,"00") -> 20 | D12: =+TEXT(A12,"mmm") -> May | E12: =+TEXT(A12,"yy") -> 25 | F12: =VLOOKUP(D12,$I$3:$J$14,2,FALSE) -> MA | G12: =+E12&F12&C12 -> 25MA20 | I12: Oct | J12: OC
A13: =+'2025'!B13 -> 45798 | B13: =DAY(A13) -> 21 | C13: =TEXT(B13,"00") -> 21 | D13: =+TEXT(A13,"mmm") -> May | E13: =+TEXT(A13,"yy") -> 25 | F13: =VLOOKUP(D13,$I$3:$J$14,2,FALSE) -> MA | G13: =+E13&F13&C13 -> 25MA21 | I13: Nov | J13: NO
A14: =+'2025'!B14 -> 45799 | B14: =DAY(A14) -> 22 | C14: =TEXT(B14,"00") -> 22 | D14: =+TEXT(A14,"mmm") -> May | E14: =+TEXT(A14,"yy") -> 25 | F14: =VLOOKUP(D14,$I$3:$J$14,2,FALSE) -> MA | G14: =+E14&F14&C14 -> 25MA22 | I14: Dec | J14: DE
A15: =+'2025'!B15 -> 45800 | B15: =DAY(A15) -> 23 | C15: =TEXT(B15,"00") -> 23 | D15: =+TEXT(A15,"mmm") -> May | E15: =+TEXT(A15,"yy") -> 25 | F15: =VLOOKUP(D15,$I$3:$J$14,2,FALSE) -> MA | G15: =+E15&F15&C15 -> 25MA23
A16: =+'2025'!B16 -> 45801 | B16: =DAY(A16) -> 24 | C16: =TEXT(B16,"00") -> 24 | D16: =+TEXT(A16,"mmm") -> May | E16: =+TEXT(A16,"yy") -> 25 | F16: =VLOOKUP(D16,$I$3:$J$14,2,FALSE) -> MA | G16: =+E16&F16&C16 -> 25MA24
A17: =+'2025'!B17 -> 45802 | B17: =DAY(A17) -> 25 | C17: =TEXT(B17,"00") -> 25 | D17: =+TEXT(A17,"mmm") -> May | E17: =+TEXT(A17,"yy") -> 25 | F17: =VLOOKUP(D17,$I$3:$J$14,2,FALSE) -> MA | G17: =+E17&F17&C17 -> 25MA25
A18: =+'2025'!B18 -> 45803 | B18: =DAY(A18) -> 26 | C18: =TEXT(B18,"00") -> 26 | D18: =+TEXT(A18,"mmm") -> May | E18: =+TEXT(A18,"yy") -> 25 | F18: =VLOOKUP(D18,$I$3:$J$14,2,FALSE) -> MA | G18: =+E18&F18&C18 -> 25MA26
A19: =+'2025'!B19 -> 45804 | B19: =DAY(A19) -> 27 | C19: =TEXT(B19,"00") -> 27 | D19: =+TEXT(A19,"mmm") -> May | E19: =+TEXT(A19,"yy") -> 25 | F19: =VLOOKUP(D19,$I$3:$J$14,2,FALSE) -> MA | G19: =+E19&F19&C19 -> 25MA27
A20: =+'2025'!B20 -> 45805 | B20: =DAY(A20) -> 28 | C20: =TEXT(B20,"00") -> 28 | D20: =+TEXT(A20,"mmm") -> May | E20: =+TEXT(A20,"yy") -> 25 | F20: =VLOOKUP(D20,$I$3:$J$14,2,FALSE) -> MA | G20: =+E20&F20&C20 -> 25MA28
A21: =+'2025'!B21 -> 45806 | B21: =DAY(A21) -> 29 | C21: =TEXT(B21,"00") -> 29 | D21: =+TEXT(A21,"mmm") -> May | E21: =+TEXT(A21,"yy") -> 25 | F21: =VLOOKUP(D21,$I$3:$J$14,2,FALSE) -> MA | G21: =+E21&F21&C21 -> 25MA29
A22: =+'2025'!B22 -> 45807 | B22: =DAY(A22) -> 30 | C22: =TEXT(B22,"00") -> 30 | D22: =+TEXT(A22,"mmm") -> May | E22: =+TEXT(A22,"yy") -> 25 | F22: =VLOOKUP(D22,$I$3:$J$14,2,FALSE) -> MA | G22: =+E22&F22&C22 -> 25MA30
A23: =+'2025'!B23 -> 45808 | B23: =DAY(A23) -> 31 | C23: =TEXT(B23,"00") -> 31 | D23: =+TEXT(A23,"mmm") -> May | E23: =+TEXT(A23,"yy") -> 25 | F23: =VLOOKUP(D23,$I$3:$J$14,2,FALSE) -> MA | G23: =+E23&F23&C23 -> 25MA31
A24: =+'2025'!B24 -> 45809 | B24: =DAY(A24) -> 1 | C24: =TEXT(B24,"00") -> 01 | D24: =+TEXT(A24,"mmm") -> Jun | E24: =+TEXT(A24,"yy") -> 25 | F24: =VLOOKUP(D24,$I$3:$J$14,2,FALSE) -> JN | G24: =+E24&F24&C24 -> 25JN01
A25: =+'2025'!B25 -> 45810 | B25: =DAY(A25) -> 2 | C25: =TEXT(B25,"00") -> 02 | D25: =+TEXT(A25,"mmm") -> Jun | E25: =+TEXT(A25,"yy") -> 25 | F25: =VLOOKUP(D25,$I$3:$J$14,2,FALSE) -> JN | G25: =+E25&F25&C25 -> 25JN02
A26: =+'2025'!B26 -> 45811 | B26: =DAY(A26) -> 3 | C26: =TEXT(B26,"00") -> 03 | D26: =+TEXT(A26,"mmm") -> Jun | E26: =+TEXT(A26,"yy") -> 25 | F26: =VLOOKUP(D26,$I$3:$J$14,2,FALSE) -> JN | G26: =+E26&F26&C26 -> 25JN03
... A33: =+'2025'!B33 -> 45818 | B33: =DAY(A33) -> 10 | C33: =TEXT(B33,"00") -> 10 | D33: =+TEXT(A33,"mmm") -> Jun | E33: =+TEXT(A33,"yy") -> 25 | F33: =VLOOKUP(D33,$I$3:$J$14,2,FALSE) -> JN | G33: =+E33&F33&C33 -> 25JN10
A34: =+'2025'!E3 -> 45819 | B34: =DAY(A34) -> 11 | C34: =TEXT(B34,"00") -> 11 | D34: =+TEXT(A34,"mmm") -> Jun | E34: =+TEXT(A34,"yy") -> 25 | F34: =VLOOKUP(D34,$I$3:$J$14,2,FALSE) -> JN | G34: =+E34&F34&C34 -> 25JN11
A35: =+'2025'!E4 -> 45820 | B35: =DAY(A35) -> 12 | C35: =TEXT(B35,"00") -> 12 | D35: =+TEXT(A35,"mmm") -> Jun | E35: =+TEXT(A35,"yy") -> 25 | F35: =VLOOKUP(D35,$I$3:$J$14,2,FALSE) -> JN | G35: =+E35&F35&C35 -> 25JN12
A36: =+'2025'!E5 -> 45821 | B36: =DAY(A36) -> 13 | C36: =TEXT(B36,"00") -> 13 | D36: =+TEXT(A36,"mmm") -> Jun | E36: =+TEXT(A36,"yy") -> 25 | F36: =VLOOKUP(D36,$I$3:$J$14,2,FALSE) -> JN | G36: =+E36&F36&C36 -> 25JN13
A37: =+'2025'!E6 -> 45822 | B37: =DAY(A37) -> 14 | C37: =TEXT(B37,"00") -> 14 | D37: =+TEXT(A37,"mmm") -> Jun | E37: =+TEXT(A37,"yy") -> 25 | F37: =VLOOKUP(D37,$I$3:$J$14,2,FALSE) -> JN | G37: =+E37&F37&C37 -> 25JN14
A38: =+'2025'!E7 -> 45823 | B38: =DAY(A38) -> 15 | C38: =TEXT(B38,"00") -> 15 | D38: =+TEXT(A38,"mmm") -> Jun | E38: =+TEXT(A38,"yy") -> 25 | F38: =VLOOKUP(D38,$I$3:$J$14,2,FALSE) -> JN | G38: =+E38&F38&C38 -> 25JN15
A39: =+'2025'!E8 -> 45824 | B39: =DAY(A39) -> 16 | C39: =TEXT(B39,"00") -> 16 | D39: =+TEXT(A39,"mmm") -> Jun | E39: =+TEXT(A39,"yy") -> 25 | F39: =VLOOKUP(D39,$I$3:$J$14,2,FALSE) -> JN | G39: =+E39&F39&C39 -> 25JN16
A40: =+'2025'!E9 -> 45825 | B40: =DAY(A40) -> 17 | C40: =TEXT(B40,"00") -> 17 | D40: =+TEXT(A40,"mmm") -> Jun | E40: =+TEXT(A40,"yy") -> 25 | F40: =VLOOKUP(D40,$I$3:$J$14,2,FALSE) -> JN | G40: =+E40&F40&C40 -> 25JN17
A41: =+'2025'!E10 -> 45826 | B41: =DAY(A41) -> 18 | C41: =TEXT(B41,"00") -> 18 | D41: =+TEXT(A41,"mmm") -> Jun | E41: =+TEXT(A41,"yy") -> 25 | F41: =VLOOKUP(D41,$I$3:$J$14,2,FALSE) -> JN | G41: =+E41&F41&C41 -> 25JN18
A42: =+'2025'!E11 -> 45827 | B42: =DAY(A42) -> 19 | C42: =TEXT(B42,"00") -> 19 | D42: =+TEXT(A42,"mmm") -> Jun | E42: =+TEXT(A42,"yy") -> 25 | F42: =VLOOKUP(D42,$I$3:$J$14,2,FALSE) -> JN | G42: =+E42&F42&C42 -> 25JN19
A43: =+'2025'!E12 -> 45828 | B43: =DAY(A43) -> 20 | C43: =TEXT(B43,"00") -> 20 | D43: =+TEXT(A43,"mmm") -> Jun | E43: =+TEXT(A43,"yy") -> 25 | F43: =VLOOKUP(D43,$I$3:$J$14,2,FALSE) -> JN | G43: =+E43&F43&C43 -> 25JN20
A44: =+'2025'!E13 -> 45829 | B44: =DAY(A44) -> 21 | C44: =TEXT(B44,"00") -> 21 | D44: =+TEXT(A44,"mmm") -> Jun | E44: =+TEXT(A44,"yy") -> 25 | F44: =VLOOKUP(D44,$I$3:$J$14,2,FALSE) -> JN | G44: =+E44&F44&C44 -> 25JN21
A45: =+'2025'!E14 -> 45830 | B45: =DAY(A45) -> 22 | C45: =TEXT(B45,"00") -> 22 | D45: =+TEXT(A45,"mmm") -> Jun | E45: =+TEXT(A45,"yy") -> 25 | F45: =VLOOKUP(D45,$I$3:$J$14,2,FALSE) -> JN | G45: =+E45&F45&C45 -> 25JN22
... A61: =+'2025'!E30 -> 45846 | B61: =DAY(A61) -> 8 | C61: =TEXT(B61,"00") -> 08 | D61: =+TEXT(A61,"mmm") -> Jul | E61: =+TEXT(A61,"yy") -> 25 | F61: =VLOOKUP(D61,$I$3:$J$14,2,FALSE) -> JL | G61: =+E61&F61&C61 -> 25JL08
A62: =+'2025'!H3 -> 45847 | B62: =DAY(A62) -> 9 | C62: =TEXT(B62,"00") -> 09 | D62: =+TEXT(A62,"mmm") -> Jul | E62: =+TEXT(A62,"yy") -> 25 | F62: =VLOOKUP(D62,$I$3:$J$14,2,FALSE) -> JL | G62: =+E62&F62&C62 -> 25JL09
A63: =+'2025'!H4 -> 45848 | B63: =DAY(A63) -> 10 | C63: =TEXT(B63,"00") -> 10 | D63: =+TEXT(A63,"mmm") -> Jul | E63: =+TEXT(A63,"yy") -> 25 | F63: =VLOOKUP(D63,$I$3:$J$14,2,FALSE) -> JL | G63: =+E63&F63&C63 -> 25JL10
...
